Workbook

Sheet Calculator
A1: ระบบคำนวณราคาใบพิมพ์ — ThaiPrint v2 (Datasheet 2025)
A2: 🟡 ช่องเหลือง = กรอก | 🟢 ช่องเขียว = ผลคำนวณ | 🔴 = เตือน | Datasheet 2025: 13 เครื่อง + Spoilage 6 แบบ
A4: ข้อมูลงาน (กรอกที่ช่องสีเหลือง)
A5: ชื่องาน | B5: โบรชัวร์ A4 4 สี
A6: ขนาดชิ้นงาน — กว้าง (ซม.) | B6: 21
A7: ขนาดชิ้นงาน — ยาว (ซม.) | B7: 29.7
A8: ขนาดกระดาษ (ใส่เครื่องโดยตรง) | B8: 24x35
A9: ชนิดกระดาษ | B9: อาร์ตมัน/ด้าน
A10: แกรม | B10: 128
A11: ราคากระดาษ (บาท/กก.) | B11: 32
A12: เครื่องพิมพ์ (Key) | B12: heidelberg_cd102
A13: จำนวนพิมพ์ (ชิ้น) | B13: 1000
A14: จำนวนสี | B14: 4
A15: ประเภทงาน (Spoilage) | B15: fourColorRepeat
A16: ประเภทหมึก | B16: Conventional
A17: วิธีพิมพ์ | B17: Sheetwise
A18: Plate Cost Mode | B18: Legacy
A19: Gripper Margin (มม., 10–15) | B19: 12
A20: Side Lay (มม., 5–10) | B20: 7
A21: Perfecting Modifier (%, 2–3, ใช้เมื่อ Perfector) | B21: 2.5
A23: ค่าที่ค้นจากตาราง (อัตโนมัติ)
A24: Sheet Width (ซม.) | B24: =IF(B8="31x43",78.74,IF(B8="25x36",63.5,IF(B8="24x35",60.96,IF(B8="19x25",48.26,B6))))
A25: Sheet Height (ซม.) | B25: =IF(B8="31x43",109.22,IF(B8="25x36",91.44,IF(B8="24x35",88.9,IF(B8="19x25",63.5,B7))))
A26: Machine Name | B26: =VLOOKUP(B12,Machines!A3:I15,2,FALSE)
A27: Machine Min W (ซม.) | B27: =VLOOKUP(B12,Machines!A3:I15,3,FALSE)
A28: Machine Min H (ซม.) | B28: =VLOOKUP(B12,Machines!A3:I15,4,FALSE)
A29: Machine Max W (ซม.) | B29: =VLOOKUP(B12,Machines!A3:I15,5,FALSE)
A30: Machine Max H (ซม.) | B30: =VLOOKUP(B12,Machines!A3:I15,6,FALSE)
A31: Plate Size | B31: =VLOOKUP(B12,Machines!A3:I15,7,FALSE)
A32: ค่าเพลท/สี (เลือก mode) | B32: =IF(B18="Datasheet2025",VLOOKUP(B12,Machines!A3:I15,9,FALSE),VLOOKUP(B12,Machines!A3:I15,8,FALSE))
A33: Plate Class (normalized) | B33: =IF(ISNUMBER(SEARCH("ตัด 4",B31)),"ตัด 4",IF(ISNUMBER(SEARCH("ตัด 2",B31)),"ตัด 2",IF(ISNUMBER(SEARCH("ตัด 1",B31)),"ตัด 2",IF(ISNUMBER(SEARCH("ตัด 8",B31)),"ตัด 4","ตัด 4"))))
A34: Spoilage Rate (%) | B34: =IF(B15="oneColorRepeat",3,IF(B15="twoColorGeneral",5,IF(B15="fourColorRepeat",8,IF(B15="fourColorFirst",10,IF(B15="uvOrPantone",10,IF(B15="specialPaper",15,5))))))
A35: Spoilage Min (ใบ) | B35: =IF(B15="oneColorRepeat",50,IF(B15="twoColorGeneral",100,IF(B15="fourColorRepeat",100,IF(B15="fourColorFirst",150,IF(B15="uvOrPantone",100,IF(B15="specialPaper",150,100))))))
A36: Effective Rate (+Perfecting) | B36: =B34+IF(B17="Perfector",B21,0)
A37: ตรวจกระดาษเข้าเครื่อง | B37: =IF(OR(AND(B24>=B27,B24<=B29,B25>=B28,B25<=B30),AND(B25>=B27,B25<=B29,B24>=B28,B24<=B30)),"✅ เข้าได้",IF(OR(B24>B29,B25>B29),"⚠️ ใหญ่เกิน","⚠️ เล็กเกิน"))
A38: หมายเหตุ Print Cost | B38: =IF(OR(ISNUMBER(SEARCH("ตัด 1",B31)),ISNUMBER(SEARCH("ตัด 8",B31))),"⚠️ ใช้อัตรา "&B33&" (ประมาณ)","")
A40: ผลคำนวณ (อัตโนมัติ)
A41: Gripper (ซม.) | B41: =B19/10
A42: Side Lay (ซม.) | B42: =B20/10
A43: Bleed รวม (ซม.) | B43: =0.6
...

Sheet Quotation
A1: บริษัท ไทยพริ้นท์ อินเตอร์กรุ๊ป จำกัด
A2: ThaiPrint Intergroup Co., Ltd.
A4: ใบเสนอราคา / QUOTATION
A6: ลูกค้า: | B6: ________________________ | D6: วันที่: | E6: =TODAY()
A7: ที่อยู่: | B7: ________________________ | D7: เลขที่: | E7: QT-2026-_____
A8: โทร: | B8: ________________________
A10: รายละเอียดงาน
A11: ชื่องาน | B11: =Calculator!B5
A12: ขนาดชิ้นงาน | B12: ="กว้าง "&Calculator!B6&" × ยาว "&Calculator!B7&" ซม."
A13: จำนวน | B13: =Calculator!B13&" ชิ้น"
A14: จำนวนสี | B14: =Calculator!B14&" สี"
A15: ประเภทกระดาษ | B15: =Calculator!B9&" "&Calculator!B10&" แกรม"
A16: ขนาดกระดาษ | B16: =Calculator!B8&" (ใส่เครื่อง)"
A17: เครื่องพิมพ์ | B17: =Calculator!B26
A18: ประเภทหมึก | B18: =Calculator!B16
A19: วิธีพิมพ์ | B19: =Calculator!B17
A20: ประเภทงาน | B20: =Calculator!B15
A22: รายการต้นทุน
A23: ลำดับ | B23: รายการ | C23: จำนวน | D23: หน่วย | E23: ราคา (บาท)
A24: 1 | B24: ค่าเพลทพิมพ์ | C24: =Calculator!B14*Calculator!B56 | D24: แผ่น | E24: =Calculator!B57
A25: 2 | B25: ค่ากระดาษ (รวม markup 20%) | C25: =Calculator!B55 | D25: ใบพิมพ์ | E25: =Calculator!B68
A26: 3 | B26: ค่าพิมพ์ | C26: =Calculator!B55 | D26: ใบพิมพ์ | E26: =Calculator!B64
B28: ยอดรวมต้นทุน | E28: =SUM(E24:E26)
B29: ราคาเสนอ (รวมทั้งหมด) | E29: =Calculator!B71
B30: ราคาต่อชิ้น | E30: =Calculator!B72
A32: หมายเหตุ:
A33: • ราคานี้ยังไม่รวม VAT 7%
A34: • ราคาเสนอมีผลภายใน 30 วัน
A35: • ระยะเวลาส่งมอบ 7-14 วันทำการหลังยืนยันแบบ
A37: ผู้เสนอราคา | D37: ผู้อนุมัติ
A38: _____________________ | D38: _____________________

Sheet Machines
A1: ตารางเครื่องพิมพ์ Heidelberg + Komori (13 รุ่น) — datasheet 2025
A2: Key | B2: ชื่อเครื่อง | C2: Min W (ซม.) | D2: Min H (ซม.) | E2: Max W (ซม.) | F2: Max H (ซม.) | G2: Plate Size | H2: ค่าเพลท Legacy | I2: ค่าเพลท Datasheet2025
A3: heidelberg_gto46 | B3: Heidelberg GTO 46 | C3: 14.8 | D3: 10.5 | E3: 46 | F3: 34 | G3: ตัด 8 (เล็ก) | H3: 200 | I3: 150
A4: heidelberg_sm52 | B4: Heidelberg SM52 | C4: 14.5 | D4: 10.5 | E4: 52 | F4: 37 | G4: ตัด 8 (กลาง) | H4: 250 | I4: 150
A5: heidelberg_gto52 | B5: Heidelberg GTO 52 | C5: 18 | D5: 10.5 | E5: 52 | F5: 36 | G5: ตัด 4 | H5: 250 | I5: 150
A6: heidelberg_mo | B6: Heidelberg MO (MOZ/MOV) | C6: 28 | D6: 21 | E6: 65 | F6: 48 | G6: ตัด 4 (B2) | H6: 300 | I6: 300
A7: heidelberg_movp | B7: Heidelberg MOVP (Perfector) | C7: 28 | D7: 21 | E7: 65 | F7: 48 | G7: ตัด 4 (B2) | H7: 300 | I7: 300
A8: heidelberg_sx52 | B8: Heidelberg SX52 | C8: 14.5 | D8: 10.5 | E8: 52 | F8: 37 | G8: ตัด 2 | H8: 450 | I8: 150
A9: heidelberg_sm74 | B9: Heidelberg SM74 | C9: 28 | D9: 21 | E9: 74 | F9: 53 | G9: ตัด 2 (B2+) | H9: 500 | I9: 500
A10: heidelberg_sx74 | B10: Heidelberg SX74 | C10: 28 | D10: 21 | E10: 74 | F10: 53 | G10: ตัด 2 | H10: 500 | I10: 500
A11: heidelberg_xl75 | B11: Heidelberg XL75 | C11: 35 | D11: 28 | E11: 74 | F11: 58.5 | G11: ตัด 2 | H11: 550 | I11: 600
A12: heidelberg_cd102 | B12: Heidelberg CD102 / XL102 | C12: 48 | D12: 34 | E12: 102 | F12: 72 | G12: ตัด 1 (B1) | H12: 600 | I12: 600
A13: heidelberg_sx102 | B13: Heidelberg SX102 | C13: 48 | D13: 34 | E13: 102 | F13: 72 | G13: ตัด 1 | H13: 650 | I13: 600
A14: heidelberg_xl106 | B14: Heidelberg XL106 | C14: 48 | D14: 34 | E14: 105 | F14: 75 | G14: ตัด 1 | H14: 700 | I14: 1000
A15: komori_s40 | B15: Komori Lithrone S40 | C15: 48 | D15: 34 | E15: 106 | F15: 75 | G15: ตัด 1 (B1) | H15: 700 | I15: 1000
A17: หมายเหตุ: ตัด N = ขนาดเพลท/เครื่อง ไม่ใช่การตัดกระดาษ • MO ห้ามใช้กระดาษ 31×43 (ใหญ่เกิน) • ใช้ Paper Cutting เพื่อตัดกระดาษโรงงานให้พอดีเครื่องเล็กกว่า

Sheet PrintCost
A1: ตารางค่าพิมพ์ Heidelberg (ตัด 4 / ตัด 2 × Conv / UV)
A2: Plate Class | B2: Ink Type | C2: ช่วงใบพิมพ์ | D2: เหมา (บาท/สี) | E2: ส่วนเกิน (บาท/ใบ/สี)
A3: ตัด 4 | B3: Conventional | C3: ≤ 10,000 ใบ | D3: 900 | E3: 0
A4: ตัด 4 | B4: Conventional | C4: > 10,000 ใบ | D4: 900 | E4: 0.1
A5: ตัด 4 | B5: UV | C5: ≤ 1,000 ใบ | D5: 1500 | E5: 0
A6: ตัด 4 | B6: UV | C6: > 1,000 ใบ | D6: 1500 | E6: 1
A7: ตัด 2 | B7: Conventional | C7: ≤ 10,000 ใบ | D7: 1200 | E7: 0
A8: ตัด 2 | B8: Conventional | C8: > 10,000 ใบ | D8: 1200 | E8: 0.2
A9: ตัด 2 | B9: UV | C9: ≤ 10,000 ใบ | D9: 2000 | E9: 0
A10: ตัด 2 | B10: UV | C10: > 10,000 ใบ | D10: 2000 | E10: 1.5
A12: Sheetwise = ค่าพิมพ์ × 2 | Work-and-Turn = × 1 | ตัด 1 → ใช้อัตรา ตัด 2 (ประมาณ) | ตัด 8 → ใช้อัตรา ตัด 4 (ประมาณ)

Sheet Spoilage
A1: Spoilage Profiles (6 แบบ) + Perfecting Modifier
A2: Job Type Key | B2: ชื่อ (ไทย) | C2: Rate (%) | D2: ขั้นต่ำ (ใบ)
A3: oneColorRepeat | B3: 1 สี ซ้ำ | C3: 3 | D3: 50
A4: twoColorGeneral | B4: 2 สี ทั่วไป | C4: 5 | D4: 100
A5: fourColorRepeat | B5: 4 สี ซ้ำ | C5: 8 | D5: 100
A6: fourColorFirst | B6: 4 สี ครั้งแรก | C6: 10 | D6: 150
A7: uvOrPantone | B7: UV / Pantone | C7: 10 | D7: 100
A8: specialPaper | B8: กระดาษพิเศษ (สติ๊กเกอร์/PVC) | C8: 15 | D8: 150
A10: Perfecting Modifier (เมื่อ printMethod = perfector)
A11: ค่า | B11: Default | C11: Min | D11: Max
A12: Perfecting +% | B12: 2.5 | C12: 2 | D12: 3
A14: สูตร: spoilageSheets = MAX(CEIL(minSheets × rate), profile.minSheets) | totalSheets = minSheets + spoilageSheets

Sheet PaperPrice
A1: ราคากระดาษต่อ กิโลกรัม (Charoen AkSorn พ.ค. 2569)
A2: ประเภทกระดาษ | B2: แกรม | C2: ยี่ห้อ/Brand | D2: ราคา/กก. (บาท)
A3: ปอนด์ (Woodfree) | B3: 60 | C3: Sky Blue / Paper Plus | D3: 31
A4: ปอนด์ (Woodfree) | B4: 70-120 | C4: Sky Blue / Paper Plus | D4: 30
A5: ปอนด์ (Woodfree) | B5: 60 | C5: UPM PEFC | D5: 32
A6: ปอนด์ (Woodfree) | B6: 70-80 | C6: UPM PEFC | D6: 31
A7: ปอนด์ (Woodfree) | B7: 60 | C7: Premium X | D7: 30
A8: ปอนด์ (Woodfree) | B8: 70-100 | C8: Premium X | D8: 29
A9: อาร์ตมัน/ด้าน | B9: 80-90 | C9: Superkote | D9: 34
A10: อาร์ตมัน/ด้าน | B10: 100-157 | C10: Superkote | D10: 32
A11: อาร์ตมัน/ด้าน | B11: 80 | C11: Nevia Spakling | D11: 33
A12: อาร์ตมัน/ด้าน | B12: 85-90 | C12: Nevia Spakling | D12: 32
A13: อาร์ตมัน/ด้าน | B13: 100-157 | C13: Nevia Spakling | D13: 31
A14: อาร์ตมัน/ด้าน | B14: 80-90 | C14: YUKI/HI-KOTE/ART-TECH | D14: 32
... A22: กระดาษการ์ดขาว | B22: 150-250 | C22: หลายยี่ห้อ | D22: 35

Sheet PaperCutting
A1: Paper Cutting Reference — กระดาษโรงงาน → ตัดเป็นชิ้นสำหรับเครื่องพิมพ์
A2: Factory Sheet | B2: ตัด (rows×cols) | C2: ชิ้น/ใบ | D2: ขนาดชิ้น (ซม.) | E2: เครื่องที่ใช้ได้ | F2: งานที่เหมาะ
A3: 31×43 นิ้ว | B3: (1,2) | C3: 2 | D3: 78.74 × 54.61 | E3: CD102, SX102, XL106, Komori S40 | F3: A1+ โปสเตอร์ใหญ่
A4: 31×43 นิ้ว | B4: (2,2) | C4: 4 | D4: 54.61 × 39.37 | E4: MO, MOVP, SM74, SX74, XL75, CD102, SX102, XL106, Komori | F4: A2+ ปก โปสเตอร์
A5: 31×43 นิ้ว | B5: (4,2) | C5: 8 | D5: 54.61 × 19.69 | E5: ไม่มี (ชิ้นยาวเกินด้านสั้นเครื่อง) | F5: ต้องตัดแบบอื่น ⚠️
A6: 31×43 นิ้ว | B6: (4,4) | C6: 16 | D6: 27.31 × 19.69 | E6: GTO46, GTO52, SM52, SX52 | F6: A4 (เสียเศษมาก ⚠️)
A7: 25×36 นิ้ว | B7: (1,1) | C7: 1 | D7: 91.44 × 63.50 | E7: CD102, SX102, XL106, Komori S40 | F7: B1
A8: 25×36 นิ้ว | B8: (2,2) | C8: 4 | D8: 45.72 × 31.75 | E8: GTO52, MO, MOVP, SM52, SX52, SM74, SX74, XL75 | F8: A3+ โปสเตอร์ A3
A9: 25×36 นิ้ว | B9: (3,3) | C9: 9 | D9: 30.48 × 21.17 | E9: GTO46, GTO52, SM52, SX52, MO, MOVP, SM74, SX74 | F9: ✅ A4 เสียเศษน้อยสุด
A10: 25×36 นิ้ว | B10: (6,6) | C10: 36 | D10: 15.24 × 10.58 | E10: GTO46, SM52, SX52 | F10: A6 นามบัตร
A11: 24×35 นิ้ว | B11: (1,1) | C11: 1 | D11: 88.90 × 60.96 | E11: CD102, SX102, XL106, Komori S40 | F11: B1-
A12: 24×35 นิ้ว | B12: (2,2) | C12: 4 | D12: 44.45 × 30.48 | E12: GTO46, GTO52, SM52, SX52, MO, MOVP, SM74, SX74, XL75 | F12: A3+
A13: 24×35 นิ้ว | B13: (2,4) | C13: 8 | D13: 44.45 × 15.24 | E13: GTO46, GTO52, SM52, SX52 | F13: งานยาว
A14: 24×35 นิ้ว | B14: (8,4) | C14: 32 | D14: 22.23 × 7.62 | E14: ไม่มี (ชิ้นเล็ก/แคบเกินเครื่อง) | F14: งานเล็กพิเศษ ⚠️
... A17: 19×25 นิ้ว | B17: (4,2) | C17: 8 | D17: 31.75 × 12.07 | E17: GTO46, GTO52, SM52, SX52 | F17: งานยาว
A19: 💡 งาน A4 → ใช้ 25×36 นิ้ว (3,3) ดีที่สุด — เสียเศษแค่ 5 มม. × 23.4 มม. | 24×35 (2,4) = 21×29.7 ก็เหมาะ ห้ามใช้ 31×43

Sheet QuickSelect
A1: Quick Select — แนะนำเครื่อง / วิธีพิมพ์ / จำนวนสี
A3: 1. แนะนำวิธีพิมพ์ตามจำนวนสั่ง
A4: จำนวนสั่ง | B4: วิธีแนะนำ | C4: เหตุผล
A5: < 500 ชิ้น | B5: Work-and-Turn | C5: ค่าเพลทประหยัดครึ่งหนึ่ง
A6: 500–2,000 ชิ้น | B6: Work-and-Turn | C6: ยังประหยัดได้ชัดเจน
A7: 2,001–5,000 ชิ้น | B7: Work-and-Turn / Sheetwise | C7: พิจารณาตามคุณภาพ
A8: > 5,000 ชิ้น | B8: Sheetwise | C8: Registration ดีกว่า
A11: 2. แนะนำเครื่องตามจำนวนสี
A12: งาน | B12: เครื่องที่แนะนำ | C12: หมายเหตุ
A13: 1–2 สี | B13: GTO52, MO | C13: —
A14: 4 สี (CMYK) | B14: GTO52, MO, SM74, XL106 | C14: —
A15: 5+ สี + Pantone/Coating | B15: GTO52, MO, SM74 | C15: 5+ unit
A16: พิมพ์ 2 ด้านรอบเดียว | B16: MOVP, SM74-2P, XL106-2P | C16: Perfector
A19: 3. แนะนำเครื่องตามขนาดกระดาษ
A20: กระดาษ | B20: เครื่องที่รองรับ | C20: หมายเหตุ
A21: ≤ 36×52 ซม. (A3+) | B21: GTO 46, GTO 52, SM52 | C21: งานเล็ก ปริมาณน้อย
A22: ≤ 48×65 ซม. | B22: MO / MOVP | C22: B2 นิยมในไทย (ตัด 4)
A23: ≤ 52×74 ซม. | B23: SX52 | C23: —
A24: 24"×35" หรือ 25"×36" | B24: SM74 / CD102 / XL106 | C24: เหมาะงาน A4 ไม่เสียเศษ
A25: ≤ 53×74 ซม. | B25: SM74 / SX74 | C25: B2+ สมรรถนะสูง
A26: ≤ 53×75 ซม. | B26: XL75 | C26: B2+ XL series
A27: ≤ 72×102 ซม. | B27: CD102 / SX102 | C27: B1
A28: ≤ 75×106 ซม. | B28: XL106 / Komori S40 | C28: B1 สมรรถนะสูงสุด
A30: ⚠️ งาน A4 ห้ามใช้กระดาษ 31×43 (เสียเศษมาก) — ใช้ 24×35 หรือ 25×36 แทน
